Workbook
Name SegmentaciónDeDatos_ALERTA_VENC.: #N/A
Name SegmentaciónDeDatos_AREA: #N/A
Name SegmentaciónDeDatos_ESTADO_SEGÚN_MORA: #N/A
Name SegmentaciónDeDatos_MES: #N/A
Name SegmentaciónDeDatos_PROVINCIA: #N/A

Sheet TABLERO COBRANZAS

Sheet CLIENTES
A1: ID Cliente | B1: Nombre Cliente | C1: Provincia
A2: Cliente 1 | B2: Cliente 1 | C2: Jujuy
A3: Cliente 2 | B3: Cliente 2 | C3: Santiago del Estero
A4: Cliente 3 | B4: Cliente 3 | C4: Catamarca
A5: Cliente 4 | B5: Cliente 4 | C5: Catamarca
A6: Cliente 5 | B6: Cliente 5 | C6: Jujuy
A7: Cliente 6 | B7: Cliente 6 | C7: Salta
A8: Cliente 7 | B8: Cliente 7 | C8: Catamarca
A9: Cliente 8 | B9: Cliente 8 | C9: Catamarca
A10: Cliente 9 | B10: Cliente 9 | C10: Catamarca
A11: Cliente 10 | B11: Cliente 10 | C11: Tucuman
A12: Cliente 11 | B12: Cliente 11 | C12: Catamarca
... A61: Cliente 60 | B61: Cliente 60 | C61: Tucuman

Sheet COTIZACION
A1: Fecha | B1: Cotizacion
A2: 45870 | B2: 1380
A3: 45873 | B3: 1375
A4: 45874 | B4: 1370
A5: 45875 | B5: 1350
A6: 45876 | B6: 1345
A7: 45877 | B7: 1340
A8: 45880 | B8: 1335
A9: 45881 | B9: 1335
A10: 45882 | B10: 1330
A11: 45883 | B11: 1325
A12: 45884 | B12: 1310
A13: 45887 | B13: 1310
... A160: 46076 | B160: 1395

Sheet DETALLES
A3: TIPO DE FACTURA | B3: SECTOR
A4: AG | B4: REPUESTOS
A5: COBRANZA | B5: COBRANZAS
A6: FACTVENTRECGAS | B6: MAQUINAS
A7: FCANTREP | B7: REPUESTOS
A8: FCELIGA | B8: REPUESTOS
A9: FCELIGA_REFACT | B9: REPUESTOS
A10: FCEMIPYME-MAQ | B10: MAQUINAS
A11: FCEMIPYME-SER | B11: SERVICIOS
A12: FCEMIPYME_REP | B12: REPUESTOS
A13: FCEMIPYME_REP_REFAC | B13: REPUESTOS
A14: FCVTASERV | B14: SERVICIOS
... A35: VentaMaquinas | B35: MAQUINAS

Sheet CALCULOS
A1: COMPOSICION DE CUENTAS
L2: velocimetro
A3: CARTERA | B3: Suma de IMP. SECUNDARIO | D3: CARTERA | E3: IMPORTE | G3: CARTERA VENCIDA | H3: IMPORTE | K3: Etiquetas de fila
A4: VENCIDO<30 | B4: 53819.99 | D4: NO VENCIDO | E4: =IFERROR(VLOOKUP(D4,$A$4:$B$9,2,0),0) -> 229959.36 | G4: VENCIDO 30 | H4: =IFERROR(VLOOKUP(G4,$A$4:$B$10,2,0),0) -> 11729.98
A5: VENCIDO 60 | B5: 2414.99 | D5: VENCIDO 30 | E5: =IFERROR(VLOOKUP(D5,$A$4:$B$8,2,0),0) -> 11729.98 | G5: VENCIDO 60 | H5: =IFERROR(VLOOKUP(G5,$A$4:$B$10,2,0),0) -> 2414.99 | K5: VENCIDO>150 | L5: =IFERROR(VLOOKUP(K5,$D$3:$E$11,2,0),0) -> 900
A6: VENCIDO 90 | B6: 828 | D6: VENCIDO 60 | E6: =IFERROR(VLOOKUP(D6,$A$4:$B$8,2,0),0) -> 2414.99 | G6: VENCIDO 90 | H6: =IFERROR(VLOOKUP(G6,$A$4:$B$10,2,0),0) -> 828 | L6: =SUM(L4:L5) -> 900
A7: NO VENCIDO | B7: 229959.36 | D7: VENCIDO 90 | E7: =IFERROR(VLOOKUP(D7,$A$4:$B$8,2,0),0) -> 828 | G7: VENCIDO<30 | H7: =IFERROR(VLOOKUP(G7,$A$4:$B$10,2,0),0) -> 53819.99
A8: VENCIDO 30 | B8: 11729.98 | D8: VENCIDO<30 | E8: =IFERROR(VLOOKUP(D8,$A$4:$B$8,2,0),0) -> 53819.99 | G8: VENCIDO>150 | H8: =IFERROR(VLOOKUP(G8,$A$4:$B$10,2,0),0) -> 900
A9: VENCIDO>150 | B9: 900 | D9: VENCIDO>150 | E9: =IFERROR(VLOOKUP(D9,$A$4:$B$10,2,0),0) -> 900 | G9: Total general | H9: =+SUM(H4:H8) -> 69692.96
A10: Total general | B10: 299652.32 | D10: Total general | E10: =SUM(E4:E9) -> 299652.32
G11: %Cartera vencida | H11: =IFERROR(TEXT(H9/E10,"0,0%"),"-") -> 23,3%
A13: VENTAS VS CARTERA
A16: VENTA | B16: Suma de IMPORTE EN DÓLAR OFICIAL | D16: Etiquetas de fila | E16: Suma de IMP. SECUNDARIO | I16: MES | J16: VENTA | K16: CARTERA
A17: DIC-12 | B17: 5891.1561 | D17: ABR-04 | E17: 2414.99 | I17: OCT-10 | J17: =IFERROR(VLOOKUP(I17,$A$17:$B$21,2,0),0) -> 9937.1865 | K17: =IFERROR(+VLOOKUP(I17,$D$16:$E$21,2,FALSE),0) -> 0
A18: ENE-01 | B18: 257883.65 | D18: AGO-08 | E18: 113897.46 | I18: NOV-11 | J18: =IFERROR(VLOOKUP(I18,$A$17:$B$21,2,0),0) -> 7264.2974 | K18: =IFERROR(+VLOOKUP(I18,$D$16:$E$21,2,FALSE),0) -> 0
A19: FEB-02 | B19: 206733.3 | D19: ENE-01 | E19: 900 | I19: DIC-12 | J19: =IFERROR(VLOOKUP(I19,$A$17:$B$21,2,0),0) -> 5891.1561 | K19: =IFERROR(+VLOOKUP(I19,$D$16:$E$21,2,FALSE),0) -> 0
A20: NOV-11 | B20: 7264.2974 | D20: JUL-07 | E20: 36133.86 | I20: ENE-01 | J20: =IFERROR(VLOOKUP(I20,$A$17:$B$21,2,0),0) -> 257883.65 | K20: =IFERROR(+VLOOKUP(I20,$D$16:$E$21,2,FALSE),0) -> 900
A21: OCT-10 | B21: 9937.1865 | D21: JUN-06 | E21: 53819.99 | I21: FEB-02 | J21: =IFERROR(VLOOKUP(I21,$A$17:$B$21,2,0),0) -> 206733.3 | K21: =IFERROR(+VLOOKUP(I21,$D$16:$E$21,2,FALSE),0) -> 0
A22: Total general | B22: 487709.59 | D22: MAR-03 | E22: 828 | I22: MAR-03 | J22: =IFERROR(VLOOKUP(I22,$A$17:$B$21,2,0),0) -> 0 | K22: =IFERROR(+VLOOKUP(I22,$D$16:$E$21,2,FALSE),0) -> 0
D23: MAY-05 | E23: 11729.98 | J23: =IFERROR(VLOOKUP(I23,$A$17:$B$20,2,0),0) -> 0 | K23: =IFERROR(+VLOOKUP(I23,$D$16:$E$21,2,FALSE),0) -> 0
D24: SEPT-09 | E24: 79928.04 | J24: =IFERROR(VLOOKUP(I24,$A$17:$B$20,2,0),0) -> 0 | K24: =IFERROR(+VLOOKUP(I24,$D$16:$E$21,2,FALSE),0) -> 0
D25: Total general | E25: 299652.32 | J25: =IFERROR(VLOOKUP(I25,$A$17:$B$20,2,0),0) -> 0 | K25: =IFERROR(+VLOOKUP(I25,$D$16:$E$21,2,FALSE),0) -> 0
J26: =IFERROR(VLOOKUP(I26,$A$17:$B$20,2,0),0) -> 0 | K26: =IFERROR(+VLOOKUP(I26,$D$16:$E$21,2,FALSE),0) -> 0
J27: =IFERROR(VLOOKUP(I27,$A$17:$B$20,2,0),0) -> 0 | K27: =IFERROR(+VLOOKUP(I27,$D$16:$E$21,2,FALSE),0) -> 0
J28: =IFERROR(VLOOKUP(I28,$A$17:$B$20,2,0),0) -> 0 | K28: =IFERROR(+VLOOKUP(I28,$D$16:$E$21,2,FALSE),0) -> 0
I29: All | J29: =SUM(J17:J28) -> 487709.59 | K29: =SUM(K17:K28) -> 900
A31: ANILLOS CARTERA
A33: Etiquetas de fila | B33: Suma de IMP. SECUNDARIO | D33: DEUDORES | E33: Suma de IMP. PRINCIPAL | F33: DIFERENCIA
A34: NO VENCIDO | B34: 0.76742059 | D34: NO VENCIDO | E34: =IFERROR(VLOOKUP(D34,$A$33:$B$39,2,FALSE),0) -> 0.76742059 | F34: =1-E34 -> 0.23257941
A35: VENCIDO 30 | B35: 0.0391453 | D35: VENCIDO<30 | E35: =IFERROR(VLOOKUP(D35,$A$33:$B$39,2,FALSE),0) -> 0.17960812 | F35: =1-E35 -> 0.82039188
A36: VENCIDO 60 | B36: 0.0080593069 | D36: VENCIDO 30 | E36: =IFERROR(VLOOKUP(D36,$A$33:$B$39,2,FALSE),0) -> 0.0391453 | F36: =1-E36 -> 0.9608547
A37: VENCIDO 90 | B37: 0.0027632024 | D37: VENCIDO 60 | E37: =IFERROR(VLOOKUP(D37,$A$33:$B$39,2,FALSE),0) -> 0.0080593069 | F37: =1-E37 -> 0.99194069
A38: VENCIDO<30 | B38: 0.17960812 | D38: VENCIDO 90 | E38: =IFERROR(VLOOKUP(D38,$A$33:$B$39,2,FALSE),0) -> 0.0027632024 | F38: =1-E38 -> 0.9972368
A39: VENCIDO>150 | B39: 0.0030034808 | D39: VENCIDO>150 | E39: =IFERROR(VLOOKUP(D39,$A$33:$B$39,2,FALSE),0) -> 0.0030034808 | F39: =1-E39 -> 0.99699652
A40: Total general | B40: 1
D42: incobrables | E42: =+E39 -> 0.0030034808
A43: GRAFICO AREA
A45: Etiquetas de fila | B45: Suma de IMP. SECUNDARIO
A46: COBRANZAS | B46: 85219.04 | D46: SECTOR | E46: VALOR
A47: MAQUINAS | B47: 96900.97 | D47: COBRANZAS | E47: =IFERROR(+VLOOKUP(D47,$A$46:$B$49,2,0),0) -> 85219.04
...

Sheet Base nueva
A1: =+TODAY() -> 46206
A2: Documento tipo | B2: FECHA COMPROBANTE | C2: CLIENTE | D2: COMPROBANTE | E2: DESCRIPCION | F2: MONEDA | G2: IMP. TRANSACCION | H2: COTIZACION | I2: IMP. PRINCIPAL | J2: IMP. SECUNDARIO | K2: FECHA VTO. | L2: DIAS DE MORA | M2: FECH | N2: MES2 | O2: MES | P2: ESTADO SEGÚN MORA | Q2: ESTADO | R2: AREA | S2: PROVINCIA | T2: ALERTA VENC.
A3: NCMAN | B3: 46239 | C3: Cliente 2 | D3: FC-1001 | E3: Facturacion mensual | F3: Dólar Divisa | G3: 4611.79 | H3: 1 | I3: 4611.79 | J3: 4611.79 | K3: 46259 | L3: =IF(COMPOSICIONSALDOneo[[#This Row],[IMP. PRINCIPAL]] > 0, MAX(0, $A$1-COMPOSICIONSALDOneo[[#This Row],[FECHA VTO.]]), 0) -> 0 | M3: =UPPER(TEXT(COMPOSICIONSALDOneo[[#This Row],[FECHA VTO.]],"MMM")) -> AGO | N3: =TEXT(MONTH(COMPOSICIONSALDOneo[[#This Row],[FECHA VTO.]]),"00") -> 08 | O3: =+CONCATENATE(COMPOSICIONSALDOneo[[#This Row],[FECH]],"-",COMPOSICIONSALDOneo[[#This Row],[MES2]]) -> AGO-08 | P3: =IF(L3=0,"NO VENCIDO",IF(L3<30,"VENCIDO<30",IF(L3<60,"VENCIDO 30",IF(L3<90,"VENCIDO 60",IF(L3<150,"VENCIDO 90","VENCIDO>150"))))) -> NO VENCIDO | Q3: =IF(COMPOSICIONSALDOneo[[#This Row],[DIAS DE MORA]]<1,"NO VENCIDO",IF(COMPOSICIONSALDOneo[[#This Row],[DIAS DE MORA]]>=1,"VENCIDO","INCOBRABLE")) -> NO VENCIDO | R3: =+VLOOKUP(COMPOSICIONSALDOneo[[#This Row],[Documento tipo]],Tabla7[#All],2,0) -> COBRANZAS | S3: =+VLOOKUP(COMPOSICIONSALDOneo[[#This Row],[CLIENTE]],Tabla5[],3,FALSE) -> Santiago del Estero | T3: =IF(COMPOSICIONSALDOneo[[#This Row],[IMP. PRINCIPAL]]<0, "No vencido", IF(AND(COMPOSICIONSALDOneo[[#This Row],[FECHA VTO.]]-TODAY()>=1, COMPOSICIONSALDOneo[[#This Row],[FECHA VTO.]]-TODAY()<=5), "Vence 2-5 días", IF(COMPOSICIONSALDOneo[[#This Row],[FECHA VTO.]]-TODAY()<0, "Vencido", "No vencido"))) -> No vencido
A4: NCCEMIPYME-REP | B4: 46011 | C4: Cliente 23 | D4: FC-1002 | E4: Insumos varios | F4: Dólares | G4: 192.17 | H4: 1 | I4: 192.17 | J4: 192.17 | K4: 46044 | L4: =IF(COMPOSICIONSALDOneo[[#This Row],[IMP. PRINCIPAL]] > 0, MAX(0, $A$1-COMPOSICIONSALDOneo[[#This Row],[FECHA VTO.]]), 0) -> 162 | M4: =UPPER(TEXT(COMPOSICIONSALDOneo[[#This Row],[FECHA VTO.]],"MMM")) -> ENE | N4: =TEXT(MONTH(COMPOSICIONSALDOneo[[#This Row],[FECHA VTO.]]),"00") -> 01 | O4: =+CONCATENATE(COMPOSICIONSALDOneo[[#This Row],[FECH]],"-",COMPOSICIONSALDOneo[[#This Row],[MES2]]) -> ENE-01 | P4: =IF(L4=0,"NO VENCIDO",IF(L4<30,"VENCIDO<30",IF(L4<60,"VENCIDO 30",IF(L4<90,"VENCIDO 60",IF(L4<150,"VENCIDO 90","VENCIDO>150"))))) -> VENCIDO>150 | Q4: =IF(COMPOSICIONSALDOneo[[#This Row],[DIAS DE MORA]]<1,"NO VENCIDO",IF(COMPOSICIONSALDOneo[[#This Row],[DIAS DE MORA]]>=1,"VENCIDO","INCOBRABLE")) -> VENCIDO | R4: =+VLOOKUP(COMPOSICIONSALDOneo[[#This Row],[Documento tipo]],Tabla7[#All],2,0) -> REPUESTOS | S4: =+VLOOKUP(COMPOSICIONSALDOneo[[#This Row],[CLIENTE]],Tabla5[],3,FALSE) -> Tucuman | T4: =IF(COMPOSICIONSALDOneo[[#This Row],[IMP. PRINCIPAL]]<0, "No vencido", IF(AND(COMPOSICIONSALDOneo[[#This Row],[FECHA VTO.]]-TODAY()>=1, COMPOSICIONSALDOneo[[#This Row],[FECHA VTO.]]-TODAY()<=5), "Vence 2-5 días", IF(COMPOSICIONSALDOneo[[#This Row],[FECHA VTO.]]-TODAY()<0, "Vencido", "No vencido"))) -> Vencido
A5: NDVI | B5: 46197 | C5: Cliente 15 | D5: FC-1003 | E5: Facturacion mensual | F5: Pesos | G5: 8681.59 | H5: 1095.1 | I5: 8681.59 | J5: 8681.59 | K5: 46234 | L5: =IF(COMPOSICIONSALDOneo[[#This Row],[IMP. PRINCIPAL]] > 0, MAX(0, $A$1-COMPOSICIONSALDOneo[[#This Row],[FECHA VTO.]]), 0) -> 0 | M5: =UPPER(TEXT(COMPOSICIONSALDOneo[[#This Row],[FECHA VTO.]],"MMM")) -> JUL | N5: =TEXT(MONTH(COMPOSICIONSALDOneo[[#This Row],[FECHA VTO.]]),"00") -> 07 | O5: =+CONCATENATE(COMPOSICIONSALDOneo[[#This Row],[FECH]],"-",COMPOSICIONSALDOneo[[#This Row],[MES2]]) -> JUL-07 | P5: =IF(L5=0,"NO VENCIDO",IF(L5<30,"VENCIDO<30",IF(L5<60,"VENCIDO 30",IF(L5<90,"VENCIDO 60",IF(L5<150,"VENCIDO 90","VENCIDO>150"))))) -> NO VENCIDO | Q5: =IF(COMPOSICIONSALDOneo[[#This Row],[DIAS DE MORA]]<1,"NO VENCIDO",IF(COMPOSICIONSALDOneo[[#This Row],[DIAS DE MORA]]>=1,"VENCIDO","INCOBRABLE")) -> NO VENCIDO | R5: =+VLOOKUP(COMPOSICIONSALDOneo[[#This Row],[Documento tipo]],Tabla7[#All],2,0) -> COBRANZAS | S5: =+VLOOKUP(COMPOSICIONSALDOneo[[#This Row],[CLIENTE]],Tabla5[],3,FALSE) -> Tucuman | T5: =IF(COMPOSICIONSALDOneo[[#This Row],[IMP. PRINCIPAL]]<0, "No vencido", IF(AND(COMPOSICIONSALDOneo[[#This Row],[FECHA VTO.]]-TODAY()>=1, COMPOSICIONSALDOneo[[#This Row],[FECHA VTO.]]-TODAY()<=5), "Vence 2-5 días", IF(COMPOSICIONSALDOneo[[#This Row],[FECHA VTO.]]-TODAY()<0, "Vencido", "No vencido"))) -> No vencido
A6: NCMAN | B6: 46118 | C6: Cliente 57 | D6: FC-1004 | E6: Mantenimiento | F6: Dólares | G6: 415.31 | H6: 1 | I6: 415.31 | J6: 415.31 | K6: 46133 | L6: =IF(COMPOSICIONSALDOneo[[#This Row],[IMP. PRINCIPAL]] > 0, MAX(0, $A$1-COMPOSICIONSALDOneo[[#This Row],[FECHA VTO.]]), 0) -> 73 | M6: =UPPER(TEXT(COMPOSICIONSALDOneo[[#This Row],[FECHA VTO.]],"MMM")) -> ABR | N6: =TEXT(MONTH(COMPOSICIONSALDOneo[[#This Row],[FECHA VTO.]]),"00") -> 04 | O6: =+CONCATENATE(COMPOSICIONSALDOneo[[#This Row],[FECH]],"-",COMPOSICIONSALDOneo[[#This Row],[MES2]]) -> ABR-04 | P6: =IF(L6=0,"NO VENCIDO",IF(L6<30,"VENCIDO<30",IF(L6<60,"VENCIDO 30",IF(L6<90,"VENCIDO 60",IF(L6<150,"VENCIDO 90","VENCIDO>150"))))) -> VENCIDO 60 | Q6: =IF(COMPOSICIONSALDOneo[[#This Row],[DIAS DE MORA]]<1,"NO VENCIDO",IF(COMPOSICIONSALDOneo[[#This Row],[DIAS DE MORA]]>=1,"VENCIDO","INCOBRABLE")) -> VENCIDO | R6: =+VLOOKUP(COMPOSICIONSALDOneo[[#This Row],[Documento tipo]],Tabla7[#All],2,0) -> COBRANZAS | S6: =+VLOOKUP(COMPOSICIONSALDOneo[[#This Row],[CLIENTE]],Tabla5[],3,FALSE) -> Catamarca | T6: =IF(COMPOSICIONSALDOneo[[#This Row],[IMP. PRINCIPAL]]<0, "No vencido", IF(AND(COMPOSICIONSALDOneo[[#This Row],[FECHA VTO.]]-TODAY()>=1, COMPOSICIONSALDOneo[[#This Row],[FECHA VTO.]]-TODAY()<=5), "Vence 2-5 días", IF(COMPOSICIONSALDOneo[[#This Row],[FECHA VTO.]]-TODAY()<0, "Vencido", "No vencido"))) -> Vencido
A7: AG | B7: 46031 | C7: Cliente 23 | D7: FC-1005 | F7: Dólar Divisa | G7: 148.64 | H7: 1 | I7: 148.64 | J7: 148.64 | K7: 46050 | L7: =IF(COMPOSICIONSALDOneo[[#This Row],[IMP. PRINCIPAL]] > 0, MAX(0, $A$1-COMPOSICIONSALDOneo[[#This Row],[FECHA VTO.]]), 0) -> 156 | M7: =UPPER(TEXT(COMPOSICIONSALDOneo[[#This Row],[FECHA VTO.]],"MMM")) -> ENE | N7: =TEXT(MONTH(COMPOSICIONSALDOneo[[#This Row],[FECHA VTO.]]),"00") -> 01 | O7: =+CONCATENATE(COMPOSICIONSALDOneo[[#This Row],[FECH]],"-",COMPOSICIONSALDOneo[[#This Row],[MES2]]) -> ENE-01 | P7: =IF(L7=0,"NO VENCIDO",IF(L7<30,"VENCIDO<30",IF(L7<60,"VENCIDO 30",IF(L7<90,"VENCIDO 60",IF(L7<150,"VENCIDO 90","VENCIDO>150"))))) -> VENCIDO>150 | Q7: =IF(COMPOSICIONSALDOneo[[#This Row],[DIAS DE MORA]]<1,"NO VENCIDO",IF(COMPOSICIONSALDOneo[[#This Row],[DIAS DE MORA]]>=1,"VENCIDO","INCOBRABLE")) -> VENCIDO | R7: =+VLOOKUP(COMPOSICIONSALDOneo[[#This Row],[Documento tipo]],Tabla7[#All],2,0) -> REPUESTOS | S7: =+VLOOKUP(COMPOSICIONSALDOneo[[#This Row],[CLIENTE]],Tabla5[],3,FALSE) -> Tucuman | T7: =IF(COMPOSICIONSALDOneo[[#This Row],[IMP. PRINCIPAL]]<0, "No vencido", IF(AND(COMPOSICIONSALDOneo[[#This Row],[FECHA VTO.]]-TODAY()>=1, COMPOSICIONSALDOneo[[#This Row],[FECHA VTO.]]-TODAY()<=5), "Vence 2-5 días", IF(COMPOSICIONSALDOneo[[#This Row],[FECHA VTO.]]-TODAY()<0, "Vencido", "No vencido"))) -> Vencido
A8: NDCDVM | B8: 46240 | C8: Cliente 38 | D8: FC-1006 | E8: OT reparacion | F8: Dólar Divisa | G8: 9924.24 | H8: 1 | I8: 9924.24 | J8: 9924.24 | K8: 46259 | L8: =IF(COMPOSICIONSALDOneo[[#This Row],[IMP. PRINCIPAL]] > 0, MAX(0, $A$1-COMPOSICIONSALDOneo[[#This Row],[FECHA VTO.]]), 0) -> 0 | M8: =UPPER(TEXT(COMPOSICIONSALDOneo[[#This Row],[FECHA VTO.]],"MMM")) -> AGO | N8: =TEXT(MONTH(COMPOSICIONSALDOneo[[#This Row],[FECHA VTO.]]),"00") -> 08 | O8: =+CONCATENATE(COMPOSICIONSALDOneo[[#This Row],[FECH]],"-",COMPOSICIONSALDOneo[[#This Row],[MES2]]) -> AGO-08 | P8: =IF(L8=0,"NO VENCIDO",IF(L8<30,"VENCIDO<30",IF(L8<60,"VENCIDO 30",IF(L8<90,"VENCIDO 60",IF(L8<150,"VENCIDO 90","VENCIDO>150"))))) -> NO VENCIDO | Q8: =IF(COMPOSICIONSALDOneo[[#This Row],[DIAS DE MORA]]<1,"NO VENCIDO",IF(COMPOSICIONSALDOneo[[#This Row],[DIAS DE MORA]]>=1,"VENCIDO","INCOBRABLE")) -> NO VENCIDO | R8: =+VLOOKUP(COMPOSICIONSALDOneo[[#This Row],[Documento tipo]],Tabla7[#All],2,0) -> MAQUINAS | S8: =+VLOOKUP(COMPOSICIONSALDOneo[[#This Row],[CLIENTE]],Tabla5[],3,FALSE) -> Catamarca | T8: =IF(COMPOSICIONSALDOneo[[#This Row],[IMP. PRINCIPAL]]<0, "No vencido", IF(AND(COMPOSICIONSALDOneo[[#This Row],[FECHA VTO.]]-TODAY()>=1, COMPOSICIONSALDOneo[[#This Row],[FECHA VTO.]]-TODAY()<=5), "Vence 2-5 días", IF(COMPOSICIONSALDOneo[[#This Row],[FECHA VTO.]]-TODAY()<0, "Vencido", "No vencido"))) -> No vencido
A9: FCELIGA_REFACT | B9: 46095 | C9: Cliente 44 | D9: FC-1007 | E9: Facturacion mensual | F9: Pesos | G9: 156.47 | H9: 1012.3 | I9: 156.47 | J9: 156.47 | K9: 46110 | L9: =IF(COMPOSICIONSALDOneo[[#This Row],[IMP. PRINCIPAL]] > 0, MAX(0, $A$1-COMPOSICIONSALDOneo[[#This Row],[FECHA VTO.]]), 0) -> 96 | M9: =UPPER(TEXT(COMPOSICIONSALDOneo[[#This Row],[FECHA VTO.]],"MMM")) -> MAR | N9: =TEXT(MONTH(COMPOSICIONSALDOneo[[#This Row],[FECHA VTO.]]),"00") -> 03 | O9: =+CONCATENATE(COMPOSICIONSALDOneo[[#This Row],[FECH]],"-",COMPOSICIONSALDOneo[[#This Row],[MES2]]) -> MAR-03 | P9: =IF(L9=0,"NO VENCIDO",IF(L9<30,"VENCIDO<30",IF(L9<60,"VENCIDO 30",IF(L9<90,"VENCIDO 60",IF(L9<150,"VENCIDO 90","VENCIDO>150"))))) -> VENCIDO 90 | Q9: =IF(COMPOSICIONSALDOneo[[#This Row],[DIAS DE MORA]]<1,"NO VENCIDO",IF(COMPOSICIONSALDOneo[[#This Row],[DIAS DE MORA]]>=1,"VENCIDO","INCOBRABLE")) -> VENCIDO | R9: =+VLOOKUP(COMPOSICIONSALDOneo[[#This Row],[Documento tipo]],Tabla7[#All],2,0) -> REPUESTOS | S9: =+VLOOKUP(COMPOSICIONSALDOneo[[#This Row],[CLIENTE]],Tabla5[],3,FALSE) -> Santiago del Estero | T9: =IF(COMPOSICIONSALDOneo[[#This Row],[IMP. PRINCIPAL]]<0, "No vencido", IF(AND(COMPOSICIONSALDOneo[[#This Row],[FECHA VTO.]]-TODAY()>=1, COMPOSICIONSALDOneo[[#This Row],[FECHA VTO.]]-TODAY()<=5), "Vence 2-5 días", IF(COMPOSICIONSALDOneo[[#This Row],[FECHA VTO.]]-TODAY()<0, "Vencido", "No vencido"))) -> Vencido
A10: FCEMIPYME_REP_REFAC | B10: 46254 | C10: Cliente 35 | D10: FC-1008 | E10: Venta repuestos | F10: Pesos | G10: 16014.59 | H10: 1030.26 | I10: 16014.59 | J10: 16014.59 | K10: 46271 | L10: =IF(COMPOSICIONSALDOneo[[#This Row],[IMP. PRINCIPAL]] > 0, MAX(0, $A$1-COMPOSICIONSALDOneo[[#This Row],[FECHA VTO.]]), 0) -> 0 | M10: =UPPER(TEXT(COMPOSICIONSALDOneo[[#This Row],[FECHA VTO.]],"MMM")) -> SEPT | N10: =TEXT(MONTH(COMPOSICIONSALDOneo[[#This Row],[FECHA VTO.]]),"00") -> 09 | O10: =+CONCATENATE(COMPOSICIONSALDOneo[[#This Row],[FECH]],"-",COMPOSICIONSALDOneo[[#This Row],[MES2]]) -> SEPT-09 | P10: =IF(L10=0,"NO VENCIDO",IF(L10<30,"VENCIDO<30",IF(L10<60,"VENCIDO 30",IF(L10<90,"VENCIDO 60",IF(L10<150,"VENCIDO 90","VENCIDO>150"))))) -> NO VENCIDO | Q10: =IF(COMPOSICIONSALDOneo[[#This Row],[DIAS DE MORA]]<1,"NO VENCIDO",IF(COMPOSICIONSALDOneo[[#This Row],[DIAS DE MORA]]>=1,"VENCIDO","INCOBRABLE")) -> NO VENCIDO | R10: =+VLOOKUP(COMPOSICIONSALDOneo[[#This Row],[Documento tipo]],Tabla7[#All],2,0) -> REPUESTOS | S10: =+VLOOKUP(COMPOSICIONSALDOneo[[#This Row],[CLIENTE]],Tabla5[],3,FALSE) -> Santiago del Estero | T10: =IF(COMPOSICIONSALDOneo[[#This Row],[IMP. PRINCIPAL]]<0, "No vencido", IF(AND(COMPOSICIONSALDOneo[[#This Row],[FECHA VTO.]]-TODAY()>=1, COMPOSICIONSALDOneo[[#This Row],[FECHA VTO.]]-TODAY()<=5), "Vence 2-5 días", IF(COMPOSICIONSALDOneo[[#This Row],[FECHA VTO.]]-TODAY()<0, "Vencido", "No vencido"))) -> No vencido
A11: NCCEMIPYME-SER | B11: 46168 | C11: Cliente 19 | D11: FC-1009 | E11: Service programado | F11: Dólares | G11: 8639.1 | H11: 1 | I11: 8639.1 | J11: 8639.1 | K11: 46196 | L11: =IF(COMPOSICIONSALDOneo[[#This Row],[IMP. PRINCIPAL]] > 0, MAX(0, $A$1-COMPOSICIONSALDOneo[[#This Row],[FECHA VTO.]]), 0) -> 10 | M11: =UPPER(TEXT(COMPOSICIONSALDOneo[[#This Row],[FECHA VTO.]],"MMM")) -> JUN | N11: =TEXT(MONTH(COMPOSICIONSALDOneo[[#This Row],[FECHA VTO.]]),"00") -> 06 | O11: =+CONCATENATE(COMPOSICIONSALDOneo[[#This Row],[FECH]],"-",COMPOSICIONSALDOneo[[#This Row],[MES2]]) -> JUN-06 | P11: =IF(L11=0,"NO VENCIDO",IF(L11<30,"VENCIDO<30",IF(L11<60,"VENCIDO 30",IF(L11<90,"VENCIDO 60",IF(L11<150,"VENCIDO 90","VENCIDO>150"))))) -> VENCIDO<30 | Q11: =IF(COMPOSICIONSALDOneo[[#This Row],[DIAS DE MORA]]<1,"NO VENCIDO",IF(COMPOSICIONSALDOneo[[#This Row],[DIAS DE MORA]]>=1,"VENCIDO","INCOBRABLE")) -> VENCIDO | R11: =+VLOOKUP(COMPOSICIONSALDOneo[[#This Row],[Documento tipo]],Tabla7[#All],2,0) -> SERVICIOS | S11: =+VLOOKUP(COMPOSICIONSALDOneo[[#This Row],[CLIENTE]],Tabla5[],3,FALSE) -> Jujuy | T11: =IF(COMPOSICIONSALDOneo[[#This Row],[IMP. PRINCIPAL]]<0, "No vencido", IF(AND(COMPOSICIONSALDOneo[[#This Row],[FECHA VTO.]]-TODAY()>=1, COMPOSICIONSALDOneo[[#This Row],[FECHA VTO.]]-TODAY()<=5), "Vence 2-5 días", IF(COMPOSICIONSALDOneo[[#This Row],[FECHA VTO.]]-TODAY()<0, "Vencido", "No vencido"))) -> Vencido
A12: FCVTASERV | B12: 46139 | C12: Cliente 31 | D12: FC-1010 | F12: Dólares | G12: 489.85 | H12: 1 | I12: 489.85 | J12: 489.85 | K12: 46171 | L12: =IF(COMPOSICIONSALDOneo[[#This Row],[IMP. PRINCIPAL]] > 0, MAX(0, $A$1-COMPOSICIONSALDOneo[[#This Row],[FECHA VTO.]]), 0) -> 35 | M12: =UPPER(TEXT(COMPOSICIONSALDOneo[[#This Row],[FECHA VTO.]],"MMM")) -> MAY | N12: =TEXT(MONTH(COMPOSICIONSALDOneo[[#This Row],[FECHA VTO.]]),"00") -> 05 | O12: =+CONCATENATE(COMPOSICIONSALDOneo[[#This Row],[FECH]],"-",COMPOSICIONSALDOneo[[#This Row],[MES2]]) -> MAY-05 | P12: =IF(L12=0,"NO VENCIDO",IF(L12<30,"VENCIDO<30",IF(L12<60,"VENCIDO 30",IF(L12<90,"VENCIDO 60",IF(L12<150,"VENCIDO 90","VENCIDO>150"))))) -> VENCIDO 30 | Q12: =IF(COMPOSICIONSALDOneo[[#This Row],[DIAS DE MORA]]<1,"NO VENCIDO",IF(COMPOSICIONSALDOneo[[#This Row],[DIAS DE MORA]]>=1,"VENCIDO","INCOBRABLE")) -> VENCIDO | R12: =+VLOOKUP(COMPOSICIONSALDOneo[[#This Row],[Documento tipo]],Tabla7[#All],2,0) -> SERVICIOS | S12: =+VLOOKUP(COMPOSICIONSALDOneo[[#This Row],[CLIENTE]],Tabla5[],3,FALSE) -> Santiago del Estero | T12: =IF(COMPOSICIONSALDOneo[[#This Row],[IMP. PRINCIPAL]]<0, "No vencido", IF(AND(COMPOSICIONSALDOneo[[#This Row],[FECHA VTO.]]-TODAY()>=1, COMPOSICIONSALDOneo[[#This Row],[FECHA VTO.]]-TODAY()<=5), "Vence 2-5 días", IF(COMPOSICIONSALDOneo[[#This Row],[FECHA VTO.]]-TODAY()<0, "Vencido", "No vencido"))) -> Vencido
A13: COBRANZA | B13: 46166 | C13: Cliente 30 | D13: FC-1011 | E13: Mantenimiento | F13: Dólar Divisa | G13: 4707.75 | H13: 1 | I13: 4707.75 | J13: 4707.75 | K13: 46201 | L13: =IF(COMPOSICIONSALDOneo[[#This Row],[IMP. PRINCIPAL]] > 0, MAX(0, $A$1-COMPOSICIONSALDOneo[[#This Row],[FECHA VTO.]]), 0) -> 5 | M13: =UPPER(TEXT(COMPOSICIONSALDOneo[[#This Row],[FECHA VTO.]],"MMM")) -> JUN | N13: =TEXT(MONTH(COMPOSICIONSALDOneo[[#This Row],[FECHA VTO.]]),"00") -> 06 | O13: =+CONCATENATE(COMPOSICIONSALDOneo[[#This Row],[FECH]],"-",COMPOSICIONSALDOneo[[#This Row],[MES2]]) -> JUN-06 | P13: =IF(L13=0,"NO VENCIDO",IF(L13<30,"VENCIDO<30",IF(L13<60,"VENCIDO 30",IF(L13<90,"VENCIDO 60",IF(L13<150,"VENCIDO 90","VENCIDO>150"))))) -> VENCIDO<30 | Q13: =IF(COMPOSICIONSALDOneo[[#This Row],[DIAS DE MORA]]<1,"NO VENCIDO",IF(COMPOSICIONSALDOneo[[#This Row],[DIAS DE MORA]]>=1,"VENCIDO","INCOBRABLE")) -> VENCIDO | R13: =+VLOOKUP(COMPOSICIONSALDOneo[[#This Row],[Documento tipo]],Tabla7[#All],2,0) -> COBRANZAS | S13: =+VLOOKUP(COMPOSICIONSALDOneo[[#This Row],[CLIENTE]],Tabla5[],3,FALSE) -> Santiago del Estero | T13: =IF(COMPOSICIONSALDOneo[[#This Row],[IMP. PRINCIPAL]]<0, "No vencido", IF(AND(COMPOSICIONSALDOneo[[#This Row],[FECHA VTO.]]-TODAY()>=1, COMPOSICIONSALDOneo[[#This Row],[FECHA VTO.]]-TODAY()<=5), "Vence 2-5 días", IF(COMPOSICIONSALDOneo[[#This Row],[FECHA VTO.]]-TODAY()<0, "Vencido", "No vencido"))) -> Vencido
A14: NCSTOCK | B14: 46126 | C14: Cliente 13 | D14: FC-1012 | E14: Mantenimiento | F14: Dólar Divisa | G14: 249.34 | H14: 1 | I14: 249.34 | J14: 249.34 | K14: 46168 | L14: =IF(COMPOSICIONSALDOneo[[#This Row],[IMP. PRINCIPAL]] > 0, MAX(0, $A$1-COMPOSICIONSALDOneo[[#This Row],[FECHA VTO.]]), 0) -> 38 | M14: =UPPER(TEXT(COMPOSICIONSALDOneo[[#This Row],[FECHA VTO.]],"MMM")) -> MAY | N14: =TEXT(MONTH(COMPOSICIONSALDOneo[[#This Row],[FECHA VTO.]]),"00") -> 05 | O14: =+CONCATENATE(COMPOSICIONSALDOneo[[#This Row],[FECH]],"-",COMPOSICIONSALDOneo[[#This Row],[MES2]]) -> MAY-05 | P14: =IF(L14=0,"NO VENCIDO",IF(L14<30,"VENCIDO<30",IF(L14<60,"VENCIDO 30",IF(L14<90,"VENCIDO 60",IF(L14<150,"VENCIDO 90","VENCIDO>150"))))) -> VENCIDO 30 | Q14: =IF(COMPOSICIONSALDOneo[[#This Row],[DIAS DE MORA]]<1,"NO VENCIDO",IF(COMPOSICIONSALDOneo[[#This Row],[DIAS DE MORA]]>=1,"VENCIDO","INCOBRABLE")) -> VENCIDO | R14: =+VLOOKUP(COMPOSICIONSALDOneo[[#This Row],[Documento tipo]],Tabla7[#All],2,0) -> REPUESTOS | S14: =+VLOOKUP(COMPOSICIONSALDOneo[[#This Row],[CLIENTE]],Tabla5[],3,FALSE) -> Tucuman | T14: =IF(COMPOSICIONSALDOneo[[#This Row],[IMP. PRINCIPAL]]<0, "No vencido", IF(AND(COMPOSICIONSALDOneo[[#This Row],[FECHA VTO.]]-TODAY()>=1, COMPOSICIONSALDOneo[[#This Row],[FECHA VTO.]]-TODAY()<=5), "Vence 2-5 días", IF(COMPOSICIONSALDOneo[[#This Row],[FECHA VTO.]]-TODAY()<0, "Vencido", "No vencido"))) -> Vencido
A15: NCCEMIPYME-SER | B15: 46168 | C15: Cliente 52 | D15: FC-1013 | E15: Servicio de PM | F15: Dólar Divisa | G15: 9880.43 | H15: 1 | I15: 9880.43 | J15: 9880.43 | K15: 46199 | L15: =IF(COMPOSICIONSALDOneo[[#This Row],[IMP. PRINCIPAL]] > 0, MAX(0, $A$1-COMPOSICIONSALDOneo[[#This Row],[FECHA VTO.]]), 0) -> 7 | M15: =UPPER(TEXT(COMPOSICIONSALDOneo[[#This Row],[FECHA VTO.]],"MMM")) -> JUN | N15: =TEXT(MONTH(COMPOSICIONSALDOneo[[#This Row],[FECHA VTO.]]),"00") -> 06 | O15: =+CONCATENATE(COMPOSICIONSALDOneo[[#This Row],[FECH]],"-",COMPOSICIONSALDOneo[[#This Row],[MES2]]) -> JUN-06 | P15: =IF(L15=0,"NO VENCIDO",IF(L15<30,"VENCIDO<30",IF(L15<60,"VENCIDO 30",IF(L15<90,"VENCIDO 60",IF(L15<150,"VENCIDO 90","VENCIDO>150"))))) -> VENCIDO<30 | Q15: =IF(COMPOSICIONSALDOneo[[#This Row],[DIAS DE MORA]]<1,"NO VENCIDO",IF(COMPOSICIONSALDOneo[[#This Row],[DIAS DE MORA]]>=1,"VENCIDO","INCOBRABLE")) -> VENCIDO | R15: =+VLOOKUP(COMPOSICIONSALDOneo[[#This Row],[Documento tipo]],Tabla7[#All],2,0) -> SERVICIOS | S15: =+VLOOKUP(COMPOSICIONSALDOneo[[#This Row],[CLIENTE]],Tabla5[],3,FALSE) -> Catamarca | T15: =IF(COMPOSICIONSALDOneo[[#This Row],[IMP. PRINCIPAL]]<0, "No vencido", IF(AND(COMPOSICIONSALDOneo[[#This Row],[FECHA VTO.]]-TODAY()>=1, COMPOSICIONSALDOneo[[#This Row],[FECHA VTO.]]-TODAY()<=5), "Vence 2-5 días", IF(COMPOSICIONSALDOneo[[#This Row],[FECHA VTO.]]-TODAY()<0, "Vencido", "No vencido"))) -> Vencido
A16: NCCEMIPYME-SER | B16: 46175 | C16: Cliente 17 | D16: FC-1014 | E16: Mantenimiento | F16: Dólares | G16: 248.46 | H16: 1 | I16: 248.46 | J16: 248.46 | K16: 46201 | L16: =IF(COMPOSICIONSALDOneo[[#This Row],[IMP. PRINCIPAL]] > 0, MAX(0, $A$1-COMPOSICIONSALDOneo[[#This Row],[FECHA VTO.]]), 0) -> 5 | M16: =UPPER(TEXT(COMPOSICIONSALDOneo[[#This Row],[FECHA VTO.]],"MMM")) -> JUN | N16: =TEXT(MONTH(COMPOSICIONSALDOneo[[#This Row],[FECHA VTO.]]),"00") -> 06 | O16: =+CONCATENATE(COMPOSICIONSALDOneo[[#This Row],[FECH]],"-",COMPOSICIONSALDOneo[[#This Row],[MES2]]) -> JUN-06 | P16: =IF(L16=0,"NO VENCIDO",IF(L16<30,"VENCIDO<30",IF(L16<60,"VENCIDO 30",IF(L16<90,"VENCIDO 60",IF(L16<150,"VENCIDO 90","VENCIDO>150"))))) -> VENCIDO<30 | Q16: =IF(COMPOSICIONSALDOneo[[#This Row],[DIAS DE MORA]]<1,"NO VENCIDO",IF(COMPOSICIONSALDOneo[[#This Row],[DIAS DE MORA]]>=1,"VENCIDO","INCOBRABLE")) -> VENCIDO | R16: =+VLOOKUP(COMPOSICIONSALDOneo[[#This Row],[Documento tipo]],Tabla7[#All],2,0) -> SERVICIOS | S16: =+VLOOKUP(COMPOSICIONSALDOneo[[#This Row],[CLIENTE]],Tabla5[],3,FALSE) -> Jujuy | T16: =IF(COMPOSICIONSALDOneo[[#This Row],[IMP. PRINCIPAL]]<0, "No vencido", IF(AND(COMPOSICIONSALDOneo[[#This Row],[FECHA VTO.]]-TODAY()>=1, COMPOSICIONSALDOneo[[#This Row],[FECHA VTO.]]-TODAY()<=5), "Vence 2-5 días", IF(COMPOSICIONSALDOneo[[#This Row],[FECHA VTO.]]-TODAY()<0, "Vencido", "No vencido"))) -> Vencido
A17: NDCDVM | B17: 46045 | C17: Cliente 42 | D17: FC-1015 | F17: Pesos | G17: 158.99 | H17: 1060.73 | I17: 158.99 | J17: 158.99 | K17: 46084 | L17: =IF(COMPOSICIONSALDOneo[[#This Row],[IMP. PRINCIPAL]] > 0, MAX(0, $A$1-COMPOSICIONSALDOneo[[#This Row],[FECHA VTO.]]), 0) -> 122 | M17: =UPPER(TEXT(COMPOSICIONSALDOneo[[#This Row],[FECHA VTO.]],"MMM")) -> MAR | N17: =TEXT(MONTH(COMPOSICIONSALDOneo[[#This Row],[FECHA VTO.]]),"00") -> 03 | O17: =+CONCATENATE(COMPOSICIONSALDOneo[[#This Row],[FECH]],"-",COMPOSICIONSALDOneo[[#This Row],[MES2]]) -> MAR-03 | P17: =IF(L17=0,"NO VENCIDO",IF(L17<30,"VENCIDO<30",IF(L17<60,"VENCIDO 30",IF(L17<90,"VENCIDO 60",IF(L17<150,"VENCIDO 90","VENCIDO>150"))))) -> VENCIDO 90 | Q17: =IF(COMPOSICIONSALDOneo[[#This Row],[DIAS DE MORA]]<1,"NO VENCIDO",IF(COMPOSICIONSALDOneo[[#This Row],[DIAS DE MORA]]>=1,"VENCIDO","INCOBRABLE")) -> VENCIDO | R17: =+VLOOKUP(COMPOSICIONSALDOneo[[#This Row],[Documento tipo]],Tabla7[#All],2,0) -> MAQUINAS | S17: =+VLOOKUP(COMPOSICIONSALDOneo[[#This Row],[CLIENTE]],Tabla5[],3,FALSE) -> Salta | T17: =IF(COMPOSICIONSALDOneo[[#This Row],[IMP. PRINCIPAL]]<0, "No vencido", IF(AND(COMPOSICIONSALDOneo[[#This Row],[FECHA VTO.]]-TODAY()>=1, COMPOSICIONSALDOneo[[#This Row],[FECHA VTO.]]-TODAY()<=5), "Vence 2-5 días", IF(COMPOSICIONSALDOneo[[#This Row],[FECHA VTO.]]-TODAY()<0, "Vencido", "No vencido"))) -> Vencido
A18: NCVDCR | B18: 46157 | C18: Cliente 18 | D18: FC-1016 | E18: Venta maquina | F18: Dólar Divisa | G18: 1489.85 | H18: 1 | I18: 1489.85 | J18: 1489.85 | K18: 46173 | L18: =IF(COMPOSICIONSALDOneo[[#This Row],[IMP. PRINCIPAL]] > 0, MAX(0, $A$1-COMPOSICIONSALDOneo[[#This Row],[FECHA VTO.]]), 0) -> 33 | M18: =UPPER(TEXT(COMPOSICIONSALDOneo[[#This Row],[FECHA VTO.]],"MMM")) -> MAY | N18: =TEXT(MONTH(COMPOSICIONSALDOneo[[#This Row],[FECHA VTO.]]),"00") -> 05 | O18: =+CONCATENATE(COMPOSICIONSALDOneo[[#This Row],[FECH]],"-",COMPOSICIONSALDOneo[[#This Row],[MES2]]) -> MAY-05 | P18: =IF(L18=0,"NO VENCIDO",IF(L18<30,"VENCIDO<30",IF(L18<60,"VENCIDO 30",IF(L18<90,"VENCIDO 60",IF(L18<150,"VENCIDO 90","VENCIDO>150"))))) -> VENCIDO 30 | Q18: =IF(COMPOSICIONSALDOneo[[#This Row],[DIAS DE MORA]]<1,"NO VENCIDO",IF(COMPOSICIONSALDOneo[[#This Row],[DIAS DE MORA]]>=1,"VENCIDO","INCOBRABLE")) -> VENCIDO | R18: =+VLOOKUP(COMPOSICIONSALDOneo[[#This Row],[Documento tipo]],Tabla7[#All],2,0) -> REPUESTOS | S18: =+VLOOKUP(COMPOSICIONSALDOneo[[#This Row],[CLIENTE]],Tabla5[],3,FALSE) -> Catamarca | T18: =IF(COMPOSICIONSALDOneo[[#This Row],[IMP. PRINCIPAL]]<0, "No vencido", IF(AND(COMPOSICIONSALDOneo[[#This Row],[FECHA VTO.]]-TODAY()>=1, COMPOSICIONSALDOneo[[#This Row],[FECHA VTO.]]-TODAY()<=5), "Vence 2-5 días", IF(COMPOSICIONSALDOneo[[#This Row],[FECHA VTO.]]-TODAY()<0, "Vencido", "No vencido"))) -> Vencido
A19: COBRANZA | B19: 46100 | C19: Cliente 18 | D19: FC-1017 | E19: Facturacion mensual | F19: Dólar Divisa | G19: 378.82 | H19: 1 | I19: 378.82 | J19: 378.82 | K19: 46134 | L19: =IF(COMPOSICIONSALDOneo[[#This Row],[IMP. PRINCIPAL]] > 0, MAX(0, $A$1-COMPOSICIONSALDOneo[[#This Row],[FECHA VTO.]]), 0) -> 72 | M19: =UPPER(TEXT(COMPOSICIONSALDOneo[[#This Row],[FECHA VTO.]],"MMM")) -> ABR | N19: =TEXT(MONTH(COMPOSICIONSALDOneo[[#This Row],[FECHA VTO.]]),"00") -> 04 | O19: =+CONCATENATE(COMPOSICIONSALDOneo[[#This Row],[FECH]],"-",COMPOSICIONSALDOneo[[#This Row],[MES2]]) -> ABR-04 | P19: =IF(L19=0,"NO VENCIDO",IF(L19<30,"VENCIDO<30",IF(L19<60,"VENCIDO 30",IF(L19<90,"VENCIDO 60",IF(L19<150,"VENCIDO 90","VENCIDO>150"))))) -> VENCIDO 60 | Q19: =IF(COMPOSICIONSALDOneo[[#This Row],[DIAS DE MORA]]<1,"NO VENCIDO",IF(COMPOSICIONSALDOneo[[#This Row],[DIAS DE MORA]]>=1,"VENCIDO","INCOBRABLE")) -> VENCIDO | R19: =+VLOOKUP(COMPOSICIONSALDOneo[[#This Row],[Documento tipo]],Tabla7[#All],2,0) -> COBRANZAS | S19: =+VLOOKUP(COMPOSICIONSALDOneo[[#This Row],[CLIENTE]],Tabla5[],3,FALSE) -> Catamarca | T19: =IF(COMPOSICIONSALDOneo[[#This Row],[IMP. PRINCIPAL]]<0, "No vencido", IF(AND(COMPOSICIONSALDOneo[[#This Row],[FECHA VTO.]]-TODAY()>=1, COMPOSICIONSALDOneo[[#This Row],[FECHA VTO.]]-TODAY()<=5), "Vence 2-5 días", IF(COMPOSICIONSALDOneo[[#This Row],[FECHA VTO.]]-TODAY()<0, "Vencido", "No vencido"))) -> Vencido
A20: NCCEMIPYME-SER | B20: 46159 | C20: Cliente 59 | D20: FC-1018 | E20: Servicio de PM | F20: Dólar Divisa | G20: 5103.09 | H20: 1 | I20: 5103.09 | J20: 5103.09 | K20: 46191 | L20: =IF(COMPOSICIONSALDOneo[[#This Row],[IMP. PRINCIPAL]] > 0, MAX(0, $A$1-COMPOSICIONSALDOneo[[#This Row],[FECHA VTO.]]), 0) -> 15 | M20: =UPPER(TEXT(COMPOSICIONSALDOneo[[#This Row],[FECHA VTO.]],"MMM")) -> JUN | N20: =TEXT(MONTH(COMPOSICIONSALDOneo[[#This Row],[FECHA VTO.]]),"00") -> 06 | O20: =+CONCATENATE(COMPOSICIONSALDOneo[[#This Row],[FECH]],"-",COMPOSICIONSALDOneo[[#This Row],[MES2]]) -> JUN-06 | P20: =IF(L20=0,"NO VENCIDO",IF(L20<30,"VENCIDO<30",IF(L20<60,"VENCIDO 30",IF(L20<90,"VENCIDO 60",IF(L20<150,"VENCIDO 90","VENCIDO>150"))))) -> VENCIDO<30 | Q20: =IF(COMPOSICIONSALDOneo[[#This Row],[DIAS DE MORA]]<1,"NO VENCIDO",IF(COMPOSICIONSALDOneo[[#This Row],[DIAS DE MORA]]>=1,"VENCIDO","INCOBRABLE")) -> VENCIDO | R20: =+VLOOKUP(COMPOSICIONSALDOneo[[#This Row],[Documento tipo]],Tabla7[#All],2,0) -> SERVICIOS | S20: =+VLOOKUP(COMPOSICIONSALDOneo[[#This Row],[CLIENTE]],Tabla5[],3,FALSE) -> Tucuman | T20: =IF(COMPOSICIONSALDOneo[[#This Row],[IMP. PRINCIPAL]]<0, "No vencido", IF(AND(COMPOSICIONSALDOneo[[#This Row],[FECHA VTO.]]-TODAY()>=1, COMPOSICIONSALDOneo[[#This Row],[FECHA VTO.]]-TODAY()<=5), "Vence 2-5 días", IF(COMPOSICIONSALDOneo[[#This Row],[FECHA VTO.]]-TODAY()<0, "Vencido", "No vencido"))) -> Vencido
A21: FVMZFLP | B21: 46260 | C21: Cliente 27 | D21: FC-1019 | E21: Venta repuestos | F21: Dólar Divisa | G21: 16187.59 | H21: 1 | I21: 16187.59 | J21: 16187.59 | K21: 46280 | L21: =IF(COMPOSICIONSALDOneo[[#This Row],[IMP. PRINCIPAL]] > 0, MAX(0, $A$1-COMPOSICIONSALDOneo[[#This Row],[FECHA VTO.]]), 0) -> 0 | M21: =UPPER(TEXT(COMPOSICIONSALDOneo[[#This Row],[FECHA VTO.]],"MMM")) -> SEPT | N21: =TEXT(MONTH(COMPOSICIONSALDOneo[[#This Row],[FECHA VTO.]]),"00") -> 09 | O21: =+CONCATENATE(COMPOSICIONSALDOneo[[#This Row],[FECH]],"-",COMPOSICIONSALDOneo[[#This Row],[MES2]]) -> SEPT-09 | P21: =IF(L21=0,"NO VENCIDO",IF(L21<30,"VENCIDO<30",IF(L21<60,"VENCIDO 30",IF(L21<90,"VENCIDO 60",IF(L21<150,"VENCIDO 90","VENCIDO>150"))))) -> NO VENCIDO | Q21: =IF(COMPOSICIONSALDOneo[[#This Row],[DIAS DE MORA]]<1,"NO VENCIDO",IF(COMPOSICIONSALDOneo[[#This Row],[DIAS DE MORA]]>=1,"VENCIDO","INCOBRABLE")) -> NO VENCIDO | R21: =+VLOOKUP(COMPOSICIONSALDOneo[[#This Row],[Documento tipo]],Tabla7[#All],2,0) -> MAQUINAS | S21: =+VLOOKUP(COMPOSICIONSALDOneo[[#This Row],[CLIENTE]],Tabla5[],3,FALSE) -> Salta | T21: =IF(COMPOSICIONSALDOneo[[#This Row],[IMP. PRINCIPAL]]<0, "No vencido", IF(AND(COMPOSICIONSALDOneo[[#This Row],[FECHA VTO.]]-TODAY()>=1, COMPOSICIONSALDOneo[[#This Row],[FECHA VTO.]]-TODAY()<=5), "Vence 2-5 días", IF(COMPOSICIONSALDOneo[[#This Row],[FECHA VTO.]]-TODAY()<0, "Vencido", "No vencido"))) -> No vencido
A22: FCEMIPYME-MAQ | B22: 46093 | C22: Cliente 58 | D22: FC-1020 | E22: Service programado | F22: Pesos | G22: 164.54 | H22: 1086.65 | I22: 164.54 | J22: 164.54 | K22: 46108 | L22: =IF(COMPOSICIONSALDOneo[[#This Row],[IMP. PRINCIPAL]] > 0, MAX(0, $A$1-COMPOSICIONSALDOneo[[#This Row],[FECHA VTO.]]), 0) -> 98 | M22: =UPPER(TEXT(COMPOSICIONSALDOneo[[#This Row],[FECHA VTO.]],"MMM")) -> MAR | N22: =TEXT(MONTH(COMPOSICIONSALDOneo[[#This Row],[FECHA VTO.]]),"00") -> 03 | O22: =+CONCATENATE(COMPOSICIONSALDOneo[[#This Row],[FECH]],"-",COMPOSICIONSALDOneo[[#This Row],[MES2]]) -> MAR-03 | P22: =IF(L22=0,"NO VENCIDO",IF(L22<30,"VENCIDO<30",IF(L22<60,"VENCIDO 30",IF(L22<90,"VENCIDO 60",IF(L22<150,"VENCIDO 90","VENCIDO>150"))))) -> VENCIDO 90 | Q22: =IF(COMPOSICIONSALDOneo[[#This Row],[DIAS DE MORA]]<1,"NO VENCIDO",IF(COMPOSICIONSALDOneo[[#This Row],[DIAS DE MORA]]>=1,"VENCIDO","INCOBRABLE")) -> VENCIDO | R22: =+VLOOKUP(COMPOSICIONSALDOneo[[#This Row],[Documento tipo]],Tabla7[#All],2,0) -> MAQUINAS | S22: =+VLOOKUP(COMPOSICIONSALDOneo[[#This Row],[CLIENTE]],Tabla5[],3,FALSE) -> Catamarca | T22: =IF(COMPOSICIONSALDOneo[[#This Row],[IMP. PRINCIPAL]]<0, "No vencido", IF(AND(COMPOSICIONSALDOneo[[#This Row],[FECHA VTO.]]-TODAY()>=1, COMPOSICIONSALDOneo[[#This Row],[FECHA VTO.]]-TODAY()<=5), "Vence 2-5 días", IF(COMPOSICIONSALDOneo[[#This Row],[FECHA VTO.]]-TODAY()<0, "Vencido", "No vencido"))) -> Vencido
A23: REC10.5 | B23: 46264 | C23: Cliente 34 | D23: FC-1021 | E23: Venta repuestos | F23: Pesos | G23: 9788.11 | H23: 1038.06 | I23: 9788.11 | J23: 9788.11 | K23: 46280 | L23: =IF(COMPOSICIONSALDOneo[[#This Row],[IMP. PRINCIPAL]] > 0, MAX(0, $A$1-COMPOSICIONSALDOneo[[#This Row],[FECHA VTO.]]), 0) -> 0 | M23: =UPPER(TEXT(COMPOSICIONSALDOneo[[#This Row],[FECHA VTO.]],"MMM")) -> SEPT | N23: =TEXT(MONTH(COMPOSICIONSALDOneo[[#This Row],[FECHA VTO.]]),"00") -> 09 | O23: =+CONCATENATE(COMPOSICIONSALDOneo[[#This Row],[FECH]],"-",COMPOSICIONSALDOneo[[#This Row],[MES2]]) -> SEPT-09 | P23: =IF(L23=0,"NO VENCIDO",IF(L23<30,"VENCIDO<30",IF(L23<60,"VENCIDO 30",IF(L23<90,"VENCIDO 60",IF(L23<150,"VENCIDO 90","VENCIDO>150"))))) -> NO VENCIDO | Q23: =IF(COMPOSICIONSALDOneo[[#This Row],[DIAS DE MORA]]<1,"NO VENCIDO",IF(COMPOSICIONSALDOneo[[#This Row],[DIAS DE MORA]]>=1,"VENCIDO","INCOBRABLE")) -> NO VENCIDO | R23: =+VLOOKUP(COMPOSICIONSALDOneo[[#This Row],[Documento tipo]],Tabla7[#All],2,0) -> MAQUINAS | S23: =+VLOOKUP(COMPOSICIONSALDOneo[[#This Row],[CLIENTE]],Tabla5[],3,FALSE) -> Jujuy | T23: =IF(COMPOSICIONSALDOneo[[#This Row],[IMP. PRINCIPAL]]<0, "No vencido", IF(AND(COMPOSICIONSALDOneo[[#This Row],[FECHA VTO.]]-TODAY()>=1, COMPOSICIONSALDOneo[[#This Row],[FECHA VTO.]]-TODAY()<=5), "Vence 2-5 días", IF(COMPOSICIONSALDOneo[[#This Row],[FECHA VTO.]]-TODAY()<0, "Vencido", "No vencido"))) -> No vencido
A24: NCCEMIPYME-SER | B24: 46124 | C24: Cliente 51 | D24: FC-1022 | E24: Facturacion mensual | F24: Dólar Divisa | G24: 245.79 | H24: 1 | I24: 245.79 | J24: 245.79 | K24: 46142 | L24: =IF(COMPOSICIONSALDOneo[[#This Row],[IMP. PRINCIPAL]] > 0, MAX(0, $A$1-COMPOSICIONSALDOneo[[#This Row],[FECHA VTO.]]), 0) -> 64 | M24: =UPPER(TEXT(COMPOSICIONSALDOneo[[#This Row],[FECHA VTO.]],"MMM")) -> ABR | N24: =TEXT(MONTH(COMPOSICIONSALDOneo[[#This Row],[FECHA VTO.]]),"00") -> 04 | O24: =+CONCATENATE(COMPOSICIONSALDOneo[[#This Row],[FECH]],"-",COMPOSICIONSALDOneo[[#This Row],[MES2]]) -> ABR-04 | P24: =IF(L24=0,"NO VENCIDO",IF(L24<30,"VENCIDO<30",IF(L24<60,"VENCIDO 30",IF(L24<90,"VENCIDO 60",IF(L24<150,"VENCIDO 90","VENCIDO>150"))))) -> VENCIDO 60 | Q24: =IF(COMPOSICIONSALDOneo[[#This Row],[DIAS DE MORA]]<1,"NO VENCIDO",IF(COMPOSICIONSALDOneo[[#This Row],[DIAS DE MORA]]>=1,"VENCIDO","INCOBRABLE")) -> VENCIDO | R24: =+VLOOKUP(COMPOSICIONSALDOneo[[#This Row],[Documento tipo]],Tabla7[#All],2,0) -> SERVICIOS | S24: =+VLOOKUP(COMPOSICIONSALDOneo[[#This Row],[CLIENTE]],Tabla5[],3,FALSE) -> Tucuman | T24: =IF(COMPOSICIONSALDOneo[[#This Row],[IMP. PRINCIPAL]]<0, "No vencido", IF(AND(COMPOSICIONSALDOneo[[#This Row],[FECHA VTO.]]-TODAY()>=1, COMPOSICIONSALDOneo[[#This Row],[FECHA VTO.]]-TODAY()<=5), "Vence 2-5 días", IF(COMPOSICIONSALDOneo[[#This Row],[FECHA VTO.]]-TODAY()<0, "Vencido", "No vencido"))) -> Vencido
A25: FCEMIPYME-SER | B25: 46143 | C25: Cliente 60 | D25: FC-1023 | E25: Servicio de PM | F25: Pesos | G25: 975.71 | H25: 1064.63 | I25: 975.71 | J25: 975.71 | K25: 46159 | L25: =IF(COMPOSICIONSALDOneo[[#This Row],[IMP. PRINCIPAL]] > 0, MAX(0, $A$1-COMPOSICIONSALDOneo[[#This Row],[FECHA VTO.]]), 0) -> 47 | M25: =UPPER(TEXT(COMPOSICIONSALDOneo[[#This Row],[FECHA VTO.]],"MMM")) -> MAY | N25: =TEXT(MONTH(COMPOSICIONSALDOneo[[#This Row],[FECHA VTO.]]),"00") -> 05 | O25: =+CONCATENATE(COMPOSICIONSALDOneo[[#This Row],[FECH]],"-",COMPOSICIONSALDOneo[[#This Row],[MES2]]) -> MAY-05 | P25: =IF(L25=0,"NO VENCIDO",IF(L25<30,"VENCIDO<30",IF(L25<60,"VENCIDO 30",IF(L25<90,"VENCIDO 60",IF(L25<150,"VENCIDO 90","VENCIDO>150"))))) -> VENCIDO 30 | Q25: =IF(COMPOSICIONSALDOneo[[#This Row],[DIAS DE MORA]]<1,"NO VENCIDO",IF(COMPOSICIONSALDOneo[[#This Row],[DIAS DE MORA]]>=1,"VENCIDO","INCOBRABLE")) -> VENCIDO | R25: =+VLOOKUP(COMPOSICIONSALDOneo[[#This Row],[Documento tipo]],Tabla7[#All],2,0) -> SERVICIOS | S25: =+VLOOKUP(COMPOSICIONSALDOneo[[#This Row],[CLIENTE]],Tabla5[],3,FALSE) -> Tucuman | T25: =IF(COMPOSICIONSALDOneo[[#This Row],[IMP. PRINCIPAL]]<0, "No vencido", IF(AND(COMPOSICIONSALDOneo[[#This Row],[FECHA VTO.]]-TODAY()>=1, COMPOSICIONSALDOneo[[#This Row],[FECHA VTO.]]-TODAY()<=5), "Vence 2-5 días", IF(COMPOSICIONSALDOneo[[#This Row],[FECHA VTO.]]-TODAY()<0, "Vencido", "No vencido"))) -> Vencido
A26: COBRANZA | B26: 46231 | C26: Cliente 11 | D26: FC-1024 | E26: Servicio de PM | F26: Pesos | G26: 16930.22 | H26: 1053.91 | I26: 16930.22 | J26: 16930.22 | K26: 46251 | L26: =IF(COMPOSICIONSALDOneo[[#This Row],[IMP. PRINCIPAL]] > 0, MAX(0, $A$1-COMPOSICIONSALDOneo[[#This Row],[FECHA VTO.]]), 0) -> 0 | M26: =UPPER(TEXT(COMPOSICIONSALDOneo[[#This Row],[FECHA VTO.]],"MMM")) -> AGO | N26: =TEXT(MONTH(COMPOSICIONSALDOneo[[#This Row],[FECHA VTO.]]),"00") -> 08 | O26: =+CONCATENATE(COMPOSICIONSALDOneo[[#This Row],[FECH]],"-",COMPOSICIONSALDOneo[[#This Row],[MES2]]) -> AGO-08 | P26: =IF(L26=0,"NO VENCIDO",IF(L26<30,"VENCIDO<30",IF(L26<60,"VENCIDO 30",IF(L26<90,"VENCIDO 60",IF(L26<150,"VENCIDO 90","VENCIDO>150"))))) -> NO VENCIDO | Q26: =IF(COMPOSICIONSALDOneo[[#This Row],[DIAS DE MORA]]<1,"NO VENCIDO",IF(COMPOSICIONSALDOneo[[#This Row],[DIAS DE MORA]]>=1,"VENCIDO","INCOBRABLE")) -> NO VENCIDO | R26: =+VLOOKUP(COMPOSICIONSALDOneo[[#This Row],[Documento tipo]],Tabla7[#All],2,0) -> COBRANZAS | S26: =+VLOOKUP(COMPOSICIONSALDOneo[[#This Row],[CLIENTE]],Tabla5[],3,FALSE) -> Catamarca | T26: =IF(COMPOSICIONSALDOneo[[#This Row],[IMP. PRINCIPAL]]<0, "No vencido", IF(AND(COMPOSICIONSALDOneo[[#This Row],[FECHA VTO.]]-TODAY()>=1, COMPOSICIONSALDOneo[[#This Row],[FECHA VTO.]]-TODAY()<=5), "Vence 2-5 días", IF(COMPOSICIONSALDOneo[[#This Row],[FECHA VTO.]]-TODAY()<0, "Vencido", "No vencido"))) -> No vencido
A27: RCM | B27: 46158 | C27: Cliente 20 | D27: FC-1025 | E27: Facturacion mensual | F27: Dólar Divisa | G27: 7733.95 | H27: 1 | I27: 7733.95 | J27: 7733.95 | K27: 46185 | L27: =IF(COMPOSICIONSALDOneo[[#This Row],[IMP. PRINCIPAL]] > 0, MAX(0, $A$1-COMPOSICIONSALDOneo[[#This Row],[FECHA VTO.]]), 0) -> 21 | M27: =UPPER(TEXT(COMPOSICIONSALDOneo[[#This Row],[FECHA VTO.]],"MMM")) -> JUN | N27: =TEXT(MONTH(COMPOSICIONSALDOneo[[#This Row],[FECHA VTO.]]),"00") -> 06 | O27: =+CONCATENATE(COMPOSICIONSALDOneo[[#This Row],[FECH]],"-",COMPOSICIONSALDOneo[[#This Row],[MES2]]) -> JUN-06 | P27: =IF(L27=0,"NO VENCIDO",IF(L27<30,"VENCIDO<30",IF(L27<60,"VENCIDO 30",IF(L27<90,"VENCIDO 60",IF(L27<150,"VENCIDO 90","VENCIDO>150"))))) -> VENCIDO<30 | Q27: =IF(COMPOSICIONSALDOneo[[#This Row],[DIAS DE MORA]]<1,"NO VENCIDO",IF(COMPOSICIONSALDOneo[[#This Row],[DIAS DE MORA]]>=1,"VENCIDO","INCOBRABLE")) -> VENCIDO | R27: =+VLOOKUP(COMPOSICIONSALDOneo[[#This Row],[Documento tipo]],Tabla7[#All],2,0) -> MAQUINAS | S27: =+VLOOKUP(COMPOSICIONSALDOneo[[#This Row],[CLIENTE]],Tabla5[],3,FALSE) -> Jujuy | T27: =IF(COMPOSICIONSALDOneo[[#This Row],[IMP. PRINCIPAL]]<0, "No vencido", IF(AND(COMPOSICIONSALDOneo[[#This Row],[FECHA VTO.]]-TODAY()>=1, COMPOSICIONSALDOneo[[#This Row],[FECHA VTO.]]-TODAY()<=5), "Vence 2-5 días", IF(COMPOSICIONSALDOneo[[#This Row],[FECHA VTO.]]-TODAY()<0, "Vencido", "No vencido"))) -> Vencido
A28: COBRANZA | B28: 46212 | C28: Cliente 54 | D28: FC-1026 | E28: OT reparacion | F28: Pesos | G28: 10951.14 | H28: 1010.74 | I28: 10951.14 | J28: 10951.14 | K28: 46237 | L28: =IF(COMPOSICIONSALDOneo[[#This Row],[IMP. PRINCIPAL]] > 0, MAX(0, $A$1-COMPOSICIONSALDOneo[[#This Row],[FECHA VTO.]]), 0) -> 0 | M28: =UPPER(TEXT(COMPOSICIONSALDOneo[[#This Row],[FECHA VTO.]],"MMM")) -> AGO | N28: =TEXT(MONTH(COMPOSICIONSALDOneo[[#This Row],[FECHA VTO.]]),"00") -> 08 | O28: =+CONCATENATE(COMPOSICIONSALDOneo[[#This Row],[FECH]],"-",COMPOSICIONSALDOneo[[#This Row],[MES2]]) -> AGO-08 | P28: =IF(L28=0,"NO VENCIDO",IF(L28<30,"VENCIDO<30",IF(L28<60,"VENCIDO 30",IF(L28<90,"VENCIDO 60",IF(L28<150,"VENCIDO 90","VENCIDO>150"))))) -> NO VENCIDO | Q28: =IF(COMPOSICIONSALDOneo[[#This Row],[DIAS DE MORA]]<1,"NO VENCIDO",IF(COMPOSICIONSALDOneo[[#This Row],[DIAS DE MORA]]>=1,"VENCIDO","INCOBRABLE")) -> NO VENCIDO | R28: =+VLOOKUP(COMPOSICIONSALDOneo[[#This Row],[Documento tipo]],Tabla7[#All],2,0) -> COBRANZAS | S28: =+VLOOKUP(COMPOSICIONSALDOneo[[#This Row],[CLIENTE]],Tabla5[],3,FALSE) -> Tucuman | T28: =IF(COMPOSICIONSALDOneo[[#This Row],[IMP. PRINCIPAL]]<0, "No vencido", IF(AND(COMPOSICIONSALDOneo[[#This Row],[FECHA VTO.]]-TODAY()>=1, COMPOSICIONSALDOneo[[#This Row],[FECHA VTO.]]-TODAY()<=5), "Vence 2-5 días", IF(COMPOSICIONSALDOneo[[#This Row],[FECHA VTO.]]-TODAY()<0, "Vencido", "No vencido"))) -> No vencido
A29: FCEMIPYME-MAQ | B29: 46140 | C29: Cliente 11 | D29: FC-1027 | E29: Venta repuestos | F29: Dólar Divisa | G29: 438.15 | H29: 1 | I29: 438.15 | J29: 438.15 | K29: 46168 | L29: =IF(COMPOSICIONSALDOneo[[#This Row],[IMP. PRINCIPAL]] > 0, MAX(0, $A$1-COMPOSICIONSALDOneo[[#This Row],[FECHA VTO.]]), 0) -> 38 | M29: =UPPER(TEXT(COMPOSICIONSALDOneo[[#This Row],[FECHA VTO.]],"MMM")) -> MAY | N29: =TEXT(MONTH(COMPOSICIONSALDOneo[[#This Row],[FECHA VTO.]]),"00") -> 05 | O29: =+CONCATENATE(COMPOSICIONSALDOneo[[#This Row],[FECH]],"-",COMPOSICIONSALDOneo[[#This Row],[MES2]]) -> MAY-05 | P29: =IF(L29=0,"NO VENCIDO",IF(L29<30,"VENCIDO<30",IF(L29<60,"VENCIDO 30",IF(L29<90,"VENCIDO 60",IF(L29<150,"VENCIDO 90","VENCIDO>150"))))) -> VENCIDO 30 | Q29: =IF(COMPOSICIONSALDOneo[[#This Row],[DIAS DE MORA]]<1,"NO VENCIDO",IF(COMPOSICIONSALDOneo[[#This Row],[DIAS DE MORA]]>=1,"VENCIDO","INCOBRABLE")) -> VENCIDO | R29: =+VLOOKUP(COMPOSICIONSALDOneo[[#This Row],[Documento tipo]],Tabla7[#All],2,0) -> MAQUINAS | S29: =+VLOOKUP(COMPOSICIONSALDOneo[[#This Row],[CLIENTE]],Tabla5[],3,FALSE) -> Catamarca | T29: =IF(COMPOSICIONSALDOneo[[#This Row],[IMP. PRINCIPAL]]<0, "No vencido", IF(AND(COMPOSICIONSALDOneo[[#This Row],[FECHA VTO.]]-TODAY()>=1, COMPOSICIONSALDOneo[[#This Row],[FECHA VTO.]]-TODAY()<=5), "Vence 2-5 días", IF(COMPOSICIONSALDOneo[[#This Row],[FECHA VTO.]]-TODAY()<0, "Vencido", "No vencido"))) -> Vencido
... A33: FCEMIPYME-MAQ | B33: 46247 | C33: Cliente 52 | D33: FC-1031 | E33: Mantenimiento | F33: Dólares | G33: 14984.12 | H33: 1 | I33: 14984.12 | J33: 14984.12 | K33: 46264 | L33: =IF(COMPOSICIONSALDOneo[[#This Row],[IMP. PRINCIPAL]] > 0, MAX(0, $A$1-COMPOSICIONSALDOneo[[#This Row],[FECHA VTO.]]), 0) -> 0 | M33: =UPPER(TEXT(COMPOSICIONSALDOneo[[#This Row],[FECHA VTO.]],"MMM")) -> AGO | N33: =TEXT(MONTH(COMPOSICIONSALDOneo[[#This Row],[FECHA VTO.]]),"00") -> 08 | O33: =+CONCATENATE(COMPOSICIONSALDOneo[[#This Row],[FECH]],"-",COMPOSICIONSALDOneo[[#This Row],[MES2]]) -> AGO-08 | P33: =IF(L33=0,"NO VENCIDO",IF(L33<30,"VENCIDO<30",IF(L33<60,"VENCIDO 30",IF(L33<90,"VENCIDO 60",IF(L33<150,"VENCIDO 90","VENCIDO>150"))))) -> NO VENCIDO | Q33: =IF(COMPOSICIONSALDOneo[[#This Row],[DIAS DE MORA]]<1,"NO VENCIDO",IF(COMPOSICIONSALDOneo[[#This Row],[DIAS DE MORA]]>=1,"VENCIDO","INCOBRABLE")) -> NO VENCIDO | R33: =+VLOOKUP(COMPOSICIONSALDOneo[[#This Row],[Documento tipo]],Tabla7[#All],2,0) -> MAQUINAS | S33: =+VLOOKUP(COMPOSICIONSALDOneo[[#This Row],[CLIENTE]],Tabla5[],3,FALSE) -> Catamarca | T33: =IF(COMPOSICIONSALDOneo[[#This Row],[IMP. PRINCIPAL]]<0, "No vencido", IF(AND(COMPOSICIONSALDOneo[[#This Row],[FECHA VTO.]]-TODAY()>=1, COMPOSICIONSALDOneo[[#This Row],[FECHA VTO.]]-TODAY()<=5), "Vence 2-5 días", IF(COMPOSICIONSALDOneo[[#This Row],[FECHA VTO.]]-TODAY()<0, "Vencido", "No vencido"))) -> No vencido
A34: RC | B34: 46160 | C34: Cliente 7 | D34: FC-1032 | F34: Dólar Divisa | G34: 6258.53 | H34: 1 | I34: 6258.53 | J34: 6258.53 | K34: 46191 | L34: =IF(COMPOSICIONSALDOneo[[#This Row],[IMP. PRINCIPAL]] > 0, MAX(0, $A$1-COMPOSICIONSALDOneo[[#This Row],[FECHA VTO.]]), 0) -> 15 | M34: =UPPER(TEXT(COMPOSICIONSALDOneo[[#This Row],[FECHA VTO.]],"MMM")) -> JUN | N34: =TEXT(MONTH(COMPOSICIONSALDOneo[[#This Row],[FECHA VTO.]]),"00") -> 06 | O34: =+CONCATENATE(COMPOSICIONSALDOneo[[#This Row],[FECH]],"-",COMPOSICIONSALDOneo[[#This Row],[MES2]]) -> JUN-06 | P34: =IF(L34=0,"NO VENCIDO",IF(L34<30,"VENCIDO<30",IF(L34<60,"VENCIDO 30",IF(L34<90,"VENCIDO 60",IF(L34<150,"VENCIDO 90","VENCIDO>150"))))) -> VENCIDO<30 | Q34: =IF(COMPOSICIONSALDOneo[[#This Row],[DIAS DE MORA]]<1,"NO VENCIDO",IF(COMPOSICIONSALDOneo[[#This Row],[DIAS DE MORA]]>=1,"VENCIDO","INCOBRABLE")) -> VENCIDO | R34: =+VLOOKUP(COMPOSICIONSALDOneo[[#This Row],[Documento tipo]],Tabla7[#All],2,0) -> REPUESTOS | S34: =+VLOOKUP(COMPOSICIONSALDOneo[[#This Row],[CLIENTE]],Tabla5[],3,FALSE) -> Catamarca | T34: =IF(COMPOSICIONSALDOneo[[#This Row],[IMP. PRINCIPAL]]<0, "No vencido", IF(AND(COMPOSICIONSALDOneo[[#This Row],[FECHA VTO.]]-TODAY()>=1, COMPOSICIONSALDOneo[[#This Row],[FECHA VTO.]]-TODAY()<=5), "Vence 2-5 días", IF(COMPOSICIONSALDOneo[[#This Row],[FECHA VTO.]]-TODAY()<0, "Vencido", "No vencido"))) -> Vencido
A35: NDVI | B35: 46075 | C35: Cliente 57 | D35: FC-1033 | E35: OT reparacion | F35: Dólar Divisa | G35: 150.59 | H35: 1 | I35: 150.59 | J35: 150.59 | K35: 46103 | L35: =IF(COMPOSICIONSALDOneo[[#This Row],[IMP. PRINCIPAL]] > 0, MAX(0, $A$1-COMPOSICIONSALDOneo[[#This Row],[FECHA VTO.]]), 0) -> 103 | M35: =UPPER(TEXT(COMPOSICIONSALDOneo[[#This Row],[FECHA VTO.]],"MMM")) -> MAR | N35: =TEXT(MONTH(COMPOSICIONSALDOneo[[#This Row],[FECHA VTO.]]),"00") -> 03 | O35: =+CONCATENATE(COMPOSICIONSALDOneo[[#This Row],[FECH]],"-",COMPOSICIONSALDOneo[[#This Row],[MES2]]) -> MAR-03 | P35: =IF(L35=0,"NO VENCIDO",IF(L35<30,"VENCIDO<30",IF(L35<60,"VENCIDO 30",IF(L35<90,"VENCIDO 60",IF(L35<150,"VENCIDO 90","VENCIDO>150"))))) -> VENCIDO 90 | Q35: =IF(COMPOSICIONSALDOneo[[#This Row],[DIAS DE MORA]]<1,"NO VENCIDO",IF(COMPOSICIONSALDOneo[[#This Row],[DIAS DE MORA]]>=1,"VENCIDO","INCOBRABLE")) -> VENCIDO | R35: =+VLOOKUP(COMPOSICIONSALDOneo[[#This Row],[Documento tipo]],Tabla7[#All],2,0) -> COBRANZAS | S35: =+VLOOKUP(COMPOSICIONSALDOneo[[#This Row],[CLIENTE]],Tabla5[],3,FALSE) -> Catamarca | T35: =IF(COMPOSICIONSALDOneo[[#This Row],[IMP. PRINCIPAL]]<0, "No vencido", IF(AND(COMPOSICIONSALDOneo[[#This Row],[FECHA VTO.]]-TODAY()>=1, COMPOSICIONSALDOneo[[#This Row],[FECHA VTO.]]-TODAY()<=5), "Vence 2-5 días", IF(COMPOSICIONSALDOneo[[#This Row],[FECHA VTO.]]-TODAY()<0, "Vencido", "No vencido"))) -> Vencido
A36: COBRANZA | B36: 46113 | C36: Cliente 23 | D36: FC-1034 | E36: Facturacion mensual | F36: Dólares | G36: 365.01 | H36: 1 | I36: 365.01 | J36: 365.01 | K36: 46139 | L36: =IF(COMPOSICIONSALDOneo[[#This Row],[IMP. PRINCIPAL]] > 0, MAX(0, $A$1-COMPOSICIONSALDOneo[[#This Row],[FECHA VTO.]]), 0) -> 67 | M36: =UPPER(TEXT(COMPOSICIONSALDOneo[[#This Row],[FECHA VTO.]],"MMM")) -> ABR | N36: =TEXT(MONTH(COMPOSICIONSALDOneo[[#This Row],[FECHA VTO.]]),"00") -> 04 | O36: =+CONCATENATE(COMPOSICIONSALDOneo[[#This Row],[FECH]],"-",COMPOSICIONSALDOneo[[#This Row],[MES2]]) -> ABR-04 | P36: =IF(L36=0,"NO VENCIDO",IF(L36<30,"VENCIDO<30",IF(L36<60,"VENCIDO 30",IF(L36<90,"VENCIDO 60",IF(L36<150,"VENCIDO 90","VENCIDO>150"))))) -> VENCIDO 60 | Q36: =IF(COMPOSICIONSALDOneo[[#This Row],[DIAS DE MORA]]<1,"NO VENCIDO",IF(COMPOSICIONSALDOneo[[#This Row],[DIAS DE MORA]]>=1,"VENCIDO","INCOBRABLE")) -> VENCIDO | R36: =+VLOOKUP(COMPOSICIONSALDOneo[[#This Row],[Documento tipo]],Tabla7[#All],2,0) -> COBRANZAS | S36: =+VLOOKUP(COMPOSICIONSALDOneo[[#This Row],[CLIENTE]],Tabla5[],3,FALSE) -> Tucuman | T36: =IF(COMPOSICIONSALDOneo[[#This Row],[IMP. PRINCIPAL]]<0, "No vencido", IF(AND(COMPOSICIONSALDOneo[[#This Row],[FECHA VTO.]]-TODAY()>=1, COMPOSICIONSALDOneo[[#This Row],[FECHA VTO.]]-TODAY()<=5), "Vence 2-5 días", IF(COMPOSICIONSALDOneo[[#This Row],[FECHA VTO.]]-TODAY()<0, "Vencido", "No vencido"))) -> Vencido
A37: NCV | B37: 46082 | C37: Cliente 5 | D37: FC-1035 | E37: Service programado | F37: Pesos | G37: 161.27 | H37: 1058.81 | I37: 161.27 | J37: 161.27 | K37: 46107 | L37: =IF(COMPOSICIONSALDOneo[[#This Row],[IMP. PRINCIPAL]] > 0, MAX(0, $A$1-COMPOSICIONSALDOneo[[#This Row],[FECHA VTO.]]), 0) -> 99 | M37: =UPPER(TEXT(COMPOSICIONSALDOneo[[#This Row],[FECHA VTO.]],"MMM")) -> MAR | N37: =TEXT(MONTH(COMPOSICIONSALDOneo[[#This Row],[FECHA VTO.]]),"00") -> 03 | O37: =+CONCATENATE(COMPOSICIONSALDOneo[[#This Row],[FECH]],"-",COMPOSICIONSALDOneo[[#This Row],[MES2]]) -> MAR-03 | P37: =IF(L37=0,"NO VENCIDO",IF(L37<30,"VENCIDO<30",IF(L37<60,"VENCIDO 30",IF(L37<90,"VENCIDO 60",IF(L37<150,"VENCIDO 90","VENCIDO>150"))))) -> VENCIDO 90 | Q37: =IF(COMPOSICIONSALDOneo[[#This Row],[DIAS DE MORA]]<1,"NO VENCIDO",IF(COMPOSICIONSALDOneo[[#This Row],[DIAS DE MORA]]>=1,"VENCIDO","INCOBRABLE")) -> VENCIDO | R37: =+VLOOKUP(COMPOSICIONSALDOneo[[#This Row],[Documento tipo]],Tabla7[#All],2,0) -> REPUESTOS | S37: =+VLOOKUP(COMPOSICIONSALDOneo[[#This Row],[CLIENTE]],Tabla5[],3,FALSE) -> Jujuy | T37: =IF(COMPOSICIONSALDOneo[[#This Row],[IMP. PRINCIPAL]]<0, "No vencido", IF(AND(COMPOSICIONSALDOneo[[#This Row],[FECHA VTO.]]-TODAY()>=1, COMPOSICIONSALDOneo[[#This Row],[FECHA VTO.]]-TODAY()<=5), "Vence 2-5 días", IF(COMPOSICIONSALDOneo[[#This Row],[FECHA VTO.]]-TODAY()<0, "Vencido", "No vencido"))) -> Vencido
A38: NCV | B38: 46139 | C38: Cliente 13 | D38: FC-1036 | E38: Venta repuestos | F38: Dólares | G38: 1463.69 | H38: 1 | I38: 1463.69 | J38: 1463.69 | K38: 46166 | L38: =IF(COMPOSICIONSALDOneo[[#This Row],[IMP. PRINCIPAL]] > 0, MAX(0, $A$1-COMPOSICIONSALDOneo[[#This Row],[FECHA VTO.]]), 0) -> 40 | M38: =UPPER(TEXT(COMPOSICIONSALDOneo[[#This Row],[FECHA VTO.]],"MMM")) -> MAY | N38: =TEXT(MONTH(COMPOSICIONSALDOneo[[#This Row],[FECHA VTO.]]),"00") -> 05 | O38: =+CONCATENATE(COMPOSICIONSALDOneo[[#This Row],[FECH]],"-",COMPOSICIONSALDOneo[[#This Row],[MES2]]) -> MAY-05 | P38: =IF(L38=0,"NO VENCIDO",IF(L38<30,"VENCIDO<30",IF(L38<60,"VENCIDO 30",IF(L38<90,"VENCIDO 60",IF(L38<150,"VENCIDO 90","VENCIDO>150"))))) -> VENCIDO 30 | Q38: =IF(COMPOSICIONSALDOneo[[#This Row],[DIAS DE MORA]]<1,"NO VENCIDO",IF(COMPOSICIONSALDOneo[[#This Row],[DIAS DE MORA]]>=1,"VENCIDO","INCOBRABLE")) -> VENCIDO | R38: =+VLOOKUP(COMPOSICIONSALDOneo[[#This Row],[Documento tipo]],Tabla7[#All],2,0) -> REPUESTOS | S38: =+VLOOKUP(COMPOSICIONSALDOneo[[#This Row],[CLIENTE]],Tabla5[],3,FALSE) -> Tucuman | T38: =IF(COMPOSICIONSALDOneo[[#This Row],[IMP. PRINCIPAL]]<0, "No vencido", IF(AND(COMPOSICIONSALDOneo[[#This Row],[FECHA VTO.]]-TODAY()>=1, COMPOSICIONSALDOneo[[#This Row],[FECHA VTO.]]-TODAY()<=5), "Vence 2-5 días", IF(COMPOSICIONSALDOneo[[#This Row],[FECHA VTO.]]-TODAY()<0, "Vencido", "No vencido"))) -> Vencido
A39: FCEMIPYME_REP_REFAC | B39: 46214 | C39: Cliente 34 | D39: FC-1037 | E39: Alquiler equipo | F39: Pesos | G39: 7109.09 | H39: 1012.09 | I39: 7109.09 | J39: 7109.09 | K39: 46244 | L39: =IF(COMPOSICIONSALDOneo[[#This Row],[IMP. PRINCIPAL]] > 0, MAX(0, $A$1-COMPOSICIONSALDOneo[[#This Row],[FECHA VTO.]]), 0) -> 0 | M39: =UPPER(TEXT(COMPOSICIONSALDOneo[[#This Row],[FECHA VTO.]],"MMM")) -> AGO | N39: =TEXT(MONTH(COMPOSICIONSALDOneo[[#This Row],[FECHA VTO.]]),"00") -> 08 | O39: =+CONCATENATE(COMPOSICIONSALDOneo[[#This Row],[FECH]],"-",COMPOSICIONSALDOneo[[#This Row],[MES2]]) -> AGO-08 | P39: =IF(L39=0,"NO VENCIDO",IF(L39<30,"VENCIDO<30",IF(L39<60,"VENCIDO 30",IF(L39<90,"VENCIDO 60",IF(L39<150,"VENCIDO 90","VENCIDO>150"))))) -> NO VENCIDO | Q39: =IF(COMPOSICIONSALDOneo[[#This Row],[DIAS DE MORA]]<1,"NO VENCIDO",IF(COMPOSICIONSALDOneo[[#This Row],[DIAS DE MORA]]>=1,"VENCIDO","INCOBRABLE")) -> NO VENCIDO | R39: =+VLOOKUP(COMPOSICIONSALDOneo[[#This Row],[Documento tipo]],Tabla7[#All],2,0) -> REPUESTOS | S39: =+VLOOKUP(COMPOSICIONSALDOneo[[#This Row],[CLIENTE]],Tabla5[],3,FALSE) -> Jujuy | T39: =IF(COMPOSICIONSALDOneo[[#This Row],[IMP. PRINCIPAL]]<0, "No vencido", IF(AND(COMPOSICIONSALDOneo[[#This Row],[FECHA VTO.]]-TODAY()>=1, COMPOSICIONSALDOneo[[#This Row],[FECHA VTO.]]-TODAY()<=5), "Vence 2-5 días", IF(COMPOSICIONSALDOneo[[#This Row],[FECHA VTO.]]-TODAY()<0, "Vencido", "No vencido"))) -> No vencido
A40: FCELIGA | B40: 46181 | C40: Cliente 17 | D40: FC-1038 | E40: Service programado | F40: Pesos | G40: 17386.83 | H40: 1033.36 | I40: 17386.83 | J40: 17386.83 | K40: 46219 | L40: =IF(COMPOSICIONSALDOneo[[#This Row],[IMP. PRINCIPAL]] > 0, MAX(0, $A$1-COMPOSICIONSALDOneo[[#This Row],[FECHA VTO.]]), 0) -> 0 | M40: =UPPER(TEXT(COMPOSICIONSALDOneo[[#This Row],[FECHA VTO.]],"MMM")) -> JUL | N40: =TEXT(MONTH(COMPOSICIONSALDOneo[[#This Row],[FECHA VTO.]]),"00") -> 07 | O40: =+CONCATENATE(COMPOSICIONSALDOneo[[#This Row],[FECH]],"-",COMPOSICIONSALDOneo[[#This Row],[MES2]]) -> JUL-07 | P40: =IF(L40=0,"NO VENCIDO",IF(L40<30,"VENCIDO<30",IF(L40<60,"VENCIDO 30",IF(L40<90,"VENCIDO 60",IF(L40<150,"VENCIDO 90","VENCIDO>150"))))) -> NO VENCIDO | Q40: =IF(COMPOSICIONSALDOneo[[#This Row],[DIAS DE MORA]]<1,"NO VENCIDO",IF(COMPOSICIONSALDOneo[[#This Row],[DIAS DE MORA]]>=1,"VENCIDO","INCOBRABLE")) -> NO VENCIDO | R40: =+VLOOKUP(COMPOSICIONSALDOneo[[#This Row],[Documento tipo]],Tabla7[#All],2,0) -> REPUESTOS | S40: =+VLOOKUP(COMPOSICIONSALDOneo[[#This Row],[CLIENTE]],Tabla5[],3,FALSE) -> Jujuy | T40: =IF(COMPOSICIONSALDOneo[[#This Row],[IMP. PRINCIPAL]]<0, "No vencido", IF(AND(COMPOSICIONSALDOneo[[#This Row],[FECHA VTO.]]-TODAY()>=1, COMPOSICIONSALDOneo[[#This Row],[FECHA VTO.]]-TODAY()<=5), "Vence 2-5 días", IF(COMPOSICIONSALDOneo[[#This Row],[FECHA VTO.]]-TODAY()<0, "Vencido", "No vencido"))) -> No vencido
A41: NCCEMIPYME-MAQ | B41: 46006 | C41: Cliente 20 | D41: FC-1039 | E41: Insumos varios | F41: Dólares | G41: 363.53 | H41: 1 | I41: 363.53 | J41: 363.53 | K41: 46044 | L41: =IF(COMPOSICIONSALDOneo[[#This Row],[IMP. PRINCIPAL]] > 0, MAX(0, $A$1-COMPOSICIONSALDOneo[[#This Row],[FECHA VTO.]]), 0) -> 162 | M41: =UPPER(TEXT(COMPOSICIONSALDOneo[[#This Row],[FECHA VTO.]],"MMM")) -> ENE | N41: =TEXT(MONTH(COMPOSICIONSALDOneo[[#This Row],[FECHA VTO.]]),"00") -> 01 | O41: =+CONCATENATE(COMPOSICIONSALDOneo[[#This Row],[FECH]],"-",COMPOSICIONSALDOneo[[#This Row],[MES2]]) -> ENE-01 | P41: =IF(L41=0,"NO VENCIDO",IF(L41<30,"VENCIDO<30",IF(L41<60,"VENCIDO 30",IF(L41<90,"VENCIDO 60",IF(L41<150,"VENCIDO 90","VENCIDO>150"))))) -> VENCIDO>150 | Q41: =IF(COMPOSICIONSALDOneo[[#This Row],[DIAS DE MORA]]<1,"NO VENCIDO",IF(COMPOSICIONSALDOneo[[#This Row],[DIAS DE MORA]]>=1,"VENCIDO","INCOBRABLE")) -> VENCIDO | R41: =+VLOOKUP(COMPOSICIONSALDOneo[[#This Row],[Documento tipo]],Tabla7[#All],2,0) -> MAQUINAS | S41: =+VLOOKUP(COMPOSICIONSALDOneo[[#This Row],[CLIENTE]],Tabla5[],3,FALSE) -> Jujuy | T41: =IF(COMPOSICIONSALDOneo[[#This Row],[IMP. PRINCIPAL]]<0, "No vencido", IF(AND(COMPOSICIONSALDOneo[[#This Row],[FECHA VTO.]]-TODAY()>=1, COMPOSICIONSALDOneo[[#This Row],[FECHA VTO.]]-TODAY()<=5), "Vence 2-5 días", IF(COMPOSICIONSALDOneo[[#This Row],[FECHA VTO.]]-TODAY()<0, "Vencido", "No vencido"))) -> Vencido
A42: NDMANUAL | B42: 46223 | C42: Cliente 36 | D42: FC-1040 | E42: Mantenimiento | F42: Pesos | G42: 14991.32 | H42: 1063.7 | I42: 14991.32 | J42: 14991.32 | K42: 46249 | L42: =IF(COMPOSICIONSALDOneo[[#This Row],[IMP. PRINCIPAL]] > 0, MAX(0, $A$1-COMPOSICIONSALDOneo[[#This Row],[FECHA VTO.]]), 0) -> 0 | M42: =UPPER(TEXT(COMPOSICIONSALDOneo[[#This Row],[FECHA VTO.]],"MMM")) -> AGO | N42: =TEXT(MONTH(COMPOSICIONSALDOneo[[#This Row],[FECHA VTO.]]),"00") -> 08 | O42: =+CONCATENATE(COMPOSICIONSALDOneo[[#This Row],[FECH]],"-",COMPOSICIONSALDOneo[[#This Row],[MES2]]) -> AGO-08 | P42: =IF(L42=0,"NO VENCIDO",IF(L42<30,"VENCIDO<30",IF(L42<60,"VENCIDO 30",IF(L42<90,"VENCIDO 60",IF(L42<150,"VENCIDO 90","VENCIDO>150"))))) -> NO VENCIDO | Q42: =IF(COMPOSICIONSALDOneo[[#This Row],[DIAS DE MORA]]<1,"NO VENCIDO",IF(COMPOSICIONSALDOneo[[#This Row],[DIAS DE MORA]]>=1,"VENCIDO","INCOBRABLE")) -> NO VENCIDO | R42: =+VLOOKUP(COMPOSICIONSALDOneo[[#This Row],[Documento tipo]],Tabla7[#All],2,0) -> COBRANZAS | S42: =+VLOOKUP(COMPOSICIONSALDOneo[[#This Row],[CLIENTE]],Tabla5[],3,FALSE) -> Jujuy | T42: =IF(COMPOSICIONSALDOneo[[#This Row],[IMP. PRINCIPAL]]<0, "No vencido", IF(AND(COMPOSICIONSALDOneo[[#This Row],[FECHA VTO.]]-TODAY()>=1, COMPOSICIONSALDOneo[[#This Row],[FECHA VTO.]]-TODAY()<=5), "Vence 2-5 días", IF(COMPOSICIONSALDOneo[[#This Row],[FECHA VTO.]]-TODAY()<0, "Vencido", "No vencido"))) -> No vencido
